Workbook

Sheet SCRAP DATA 24 -25 fy (2)
A1: Month | B1: Year | C1: Prod Type | D1: PRODUCT | E1: Qty | F1: Unit Cost | G1: Total Cost | H1: Scrap Type
A2: Jul | B2: 2024 | C2: Hammer | D2: Ham Club 1.8kg S/C Soft Grip | E2: 2 | F2: 129.29 | G2: =E2*F2 -> 258.58 | H2: F/fault
A3: Jul | B3: 2024 | C3: Hammer | D3: Ham Scutch S/C Soft Grip | E3: 3 | F3: 87.06 | G3: =E3*F3 -> 261.18 | H3: F/fault
A4: Jul | B4: 2024 | C4: Hammer | D4: Ham Drill 1.8kg P/Handle Black | E4: 1 | F4: 96.65 | G4: =E4*F4 -> 96.65 | H4: DAM.EYE
A5: Jul | B5: 2024 | C5: Iron Tools | D5: Bolst Electrician 55mm | E5: 2 | F5: 33.33 | G5: =E5*F5 -> 66.66 | H5: BAD.FRG
A6: Jul | B6: 2024 | C6: Iron Tools | D6: Bolster 100mm | E6: 7 | F6: 47.43 | G6: =E6*F6 -> 332.01 | H6: U.FILL
A7: Jul | B7: 2024 | C7: Iron Tools | D7: Chisel Flat Cold 16x175 | E7: 2 | F7: 18.44 | G7: =E7*F7 -> 36.88 | H7: WL.DAM
A8: Jul | B8: 2024 | C8: Iron Tools | D8: Chisel Flat Cold 12x200 | E8: 3 | F8: 19.14 | G8: =E8*F8 -> 57.42 | H8: WL.DAM
A9: Jul | B9: 2024 | C9: Iron Tools | D9: Chisel Flat Cold 20x200 | E9: 5 | F9: 26.49 | G9: =E9*F9 -> 132.45 | H9: WL.DAM
A10: Jul | B10: 2024 | C10: Iron Tools | D10: Chisel Flat Cold 25x300 | E10: 4 | F10: 44.53 | G10: =E10*F10 -> 178.12 | H10: WL.DAM
A11: Jul | B11: 2024 | C11: Iron Tools | D11: Chisel Flat Cold 25x350 | E11: 4 | F11: 48.39 | G11: =E11*F11 -> 193.56 | H11: WL.DAM
A12: Jul | B12: 2024 | C12: Iron Tools | D12: Bar Wrecking 20x450mm | E12: 2 | F12: 60.91 | G12: =E12*F12 -> 121.82 | H12: WL.DAM
A13: Jul | B13: 2024 | C13: Iron Tools | D13: Bar Wrecking 20x600mm | E13: 2 | F13: 72.41 | G13: =E13*F13 -> 144.82 | H13: WL.DAM
... A199: JUNE | B199: 2024 | C199: Handles | D199: HDL Claw Poly S/C Soft Grip | E199: 32 | F199: 19.68 | G199: =E199*F199 -> 629.76 | H199: PLSTC.MOULD.DEFECT
A200: JUL | B200: 2024 | C200: Hammer | D200: Ham Claw 500g Poly | E200: 4 | F200: =VLOOKUP(D200,TABLE!$B$1:$C$137,2,FALSE) -> 72.31 | G200: =E200*F200 -> 289.24 | H200: CLW END.SHRT
A201: JUL | B201: 2024 | C201: Hammer | D201: Ham Drill 1.8kg P/Handle Black | E201: 13 | F201: =VLOOKUP(D201,TABLE!$B$1:$C$137,2,FALSE) -> 114.33 | G201: =E201*F201 -> 1486.29 | H201: BAD.FRG
A202: JUL | B202: 2024 | C202: Hammer | D202: Ham Spalling 6.3kg P/Handle Black CCL | E202: 5 | F202: =VLOOKUP(D202,TABLE!$B$1:$C$137,2,FALSE) -> 358.99 | G202: =E202*F202 -> 1794.95 | H202: CRACKSF/fault
A203: JUL | B203: 2024 | C203: Hammer | D203: Ham Claw 700g S/C Poly Handle | E203: 2 | F203: =VLOOKUP(D203,TABLE!$B$1:$C$137,2,FALSE) -> 85.75 | G203: =E203*F203 -> 171.5 | H203: CLW END.SHRT
A204: JUL | B204: 2024 | C204: Hammer | D204: Ham BP 500g N/C Soft Grip | E204: 6 | F204: =VLOOKUP(D204,TABLE!$B$1:$C$137,2,FALSE) -> 77.69 | G204: =E204*F204 -> 466.14 | H204: DAM.EYE
A205: JUL | B205: 2024 | C205: Hammer | D205: Ham Club 1.1kg S/C Soft Grip | E205: 3 | F205: =VLOOKUP(D205,TABLE!$B$1:$C$137,2,FALSE) -> 97.22 | G205: =E205*F205 -> 291.66 | H205: DAM.EYE
A206: JUL | B206: 2024 | C206: Hammer | D206: Ham Club 1.8kg S/C Soft Grip | E206: 10 | F206: =VLOOKUP(D206,TABLE!$B$1:$C$137,2,FALSE) -> 85 | G206: =E206*F206 -> 850 | H206: DAM.EYE
A207: JUL | B207: 2024 | C207: Iron Tools | D207: Bolst Electrician 55mm | E207: 3 | F207: =VLOOKUP(D207,TABLE!$B$1:$C$137,2,FALSE) -> 32.32 | G207: =E207*F207 -> 96.96 | H207: WL.DAM
A208: JUL | B208: 2024 | C208: Iron Tools | D208: Chisel Flat Cold 12x150 | E208: 3 | F208: =VLOOKUP(D208,TABLE!$B$1:$C$137,2,FALSE) -> 16.08 | G208: =E208*F208 -> 48.24 | H208: WL.DAM
A209: JUL | B209: 2024 | C209: Iron Tools | D209: Chisel Flat Cold 20x200 | E209: 2 | F209: =VLOOKUP(D209,TABLE!$B$1:$C$137,2,FALSE) -> 23.91 | G209: =E209*F209 -> 47.82 | H209: WL.DAM
A210: JUL | B210: 2024 | C210: Iron Tools | D210: Chisel Flat Cold 20x250 | E210: 2 | F210: =VLOOKUP(D210,TABLE!$B$1:$C$137,2,FALSE) -> 27.14 | G210: =E210*F210 -> 54.28 | H210: WL.DAM
A211: JUL | B211: 2024 | C211: Iron Tools | D211: Chisel Flat Cold 25x250 | E211: 7 | F211: =VLOOKUP(D211,TABLE!$B$1:$C$137,2,FALSE) -> 34.83 | G211: =E211*F211 -> 243.81 | H211: WL.DAM
... A256: SEP | B256: 2024 | C256: Hammer | D256: Ham Club 1.8kg S/C Soft Grip | E256: 4 | F256: =VLOOKUP(D256,TABLE!$B$1:$C$137,2,FALSE) -> 85 | G256: =E256*F256 -> 340 | H256: DAM.EYE
A257: SEP | B257: 2024 | C257: Hammer | D257: Rake Head | E257: 8 | F257: 86.52 | G257: 692.16 | H257: MOULDING PROBLEM
A258: SEP | B258: 2024 | C258: Iron Tools | D258: Bolster 100mm | E258: 9 | F258: =VLOOKUP(D258,TABLE!$B$1:$C$137,2,FALSE) -> 49.25 | G258: =E258*F258 -> 443.25 | H258: BAD.FRG
A259: SEP | B259: 2024 | C259: Iron Tools | D259: Chisel Flat Cold 25x350 | E259: 7 | F259: =VLOOKUP(D259,TABLE!$B$1:$C$137,2,FALSE) -> 44.78 | G259: =E259*F259 -> 313.46 | H259: BAD.FRG
A260: SEP | B260: 2024 | C260: Iron Tools | D260: Chisel Flat Cold 22x225 | E260: 3 | F260: =VLOOKUP(D260,TABLE!$B$1:$C$137,2,FALSE) -> 26.1 | G260: =E260*F260 -> 78.3 | H260: WL.DAM
A261: SEP | B261: 2024 | C261: Iron Tools | D261: Chisel Flat Cold 20x250 | E261: 7 | F261: =VLOOKUP(D261,TABLE!$B$1:$C$137,2,FALSE) -> 27.14 | G261: =E261*F261 -> 189.98 | H261: WL.DAM
A262: SEP | B262: 2024 | C262: Handles | D262: Hdl Boiler Scaling Wood | E262: 3 | F262: =VLOOKUP(D262,TABLE!$B$1:$C$137,2,FALSE) -> 7.62 | G262: =E262*F262 -> 22.86 | H262: BRKN
A263: SEP | B263: 2024 | C263: Handles | D263: Hdl Rake Steel Plastic | E263: 10 | F263: =VLOOKUP(D263,TABLE!$B$1:$C$137,2,FALSE) -> 11.59 | G263: =E263*F263 -> 115.9 | H263: BRKN
A264: OCT | B264: 2024 | C264: Hammer | D264: Ham Claw 500g Poly | E264: 14 | F264: =VLOOKUP(D264,TABLE!$B$1:$C$137,2,FALSE) -> 72.31 | G264: =E264*F264 -> 1012.34 | H264: BAD.FRG
A265: OCT | B265: 2024 | C265: Hammer | D265: Ham Drill 1.8kg P/Handle Black | E265: 13 | F265: =VLOOKUP(D265,TABLE!$B$1:$C$137,2,FALSE) -> 114.33 | G265: =E265*F265 -> 1486.29 | H265: BAD.FRG
A266: OCT | B266: 2024 | C266: Hammer | D266: Ham Sledge 6.3kg P/Handle Black CCL | E266: 1 | F266: =VLOOKUP(D266,TABLE!$B$1:$C$137,2,FALSE) -> 358 | G266: =E266*F266 -> 358 | H266: BAD.FRG
A267: OCT | B267: 2024 | C267: Hammer | D267: Ham BP 1100 N/C Soft Grip | E267: 1 | F267: =VLOOKUP(D267,TABLE!$B$1:$C$137,2,FALSE) -> 115.36 | G267: =E267*F267 -> 115.36 | H267: BAD.FRG
A268: OCT | B268: 2024 | C268: Hammer | D268: Ham Club 1.1kg S/C Soft Grip | E268: 2 | F268: =VLOOKUP(D268,TABLE!$B$1:$C$137,2,FALSE) -> 97.22 | G268: =E268*F268 -> 194.44 | H268: BAD.FRG
A269: OCT | B269: 2024 | C269: Hammer | D269: Ham Club 1.8kg S/C Soft Grip | E269: 6 | F269: =VLOOKUP(D269,TABLE!$B$1:$C$137,2,FALSE) -> 85 | G269: =E269*F269 -> 510 | H269: BAD.FRG
...

Sheet SCRAP DATATABLE
A1: HAMMERE ITEM | B1: Hammer | C1: VALUE | E1: Iron tools ITEM | F1: Iron tools | G1: VALUE | I1: Iron Handles ITEM | J1: Handles | K1: VALUE | O1: Scrap type | P1: Product type
A2: 1 | B2: Ham Sledge 1.8kg RW Wood | C2: 148.95 | E2: 1 | F2: Bolster 100mm | G2: 47.43 | I2: 1 | J2: HDL Drill 1.8 kg CB Poly Black | K2: 15.83 | M2: BAD | N2: SCAL | O2: =_xlfn.TEXTJOIN(,TRUE,M2,N2) -> BADSCAL | P2: Hammer
A3: 2 | B3: Ham Sledge 3.6kg RW Wood | C3: 223.33 | E3: 2 | F3: Bolster 100mm PVC Grip | G3: 56.81 | I3: 2 | J3: HDLSledge 3.6kg Poly Black | K3: 52.49 | M3: CRACKS | N3: F/fault | O3: =_xlfn.TEXTJOIN( ,TRUE,M3,N3) -> CRACKSF/fault | P3: Iron tools
A4: 3 | B4: Ham Sledge 4.5kg RW Wood | E4: 3 | F4: Bolst Electrician 55mm | G4: 33.33 | I4: 3 | J4: HDLSledge 6.3kg Poly Black | K4: 58 | N4: H.T. | O4: =_xlfn.TEXTJOIN( ,TRUE,M4,N4) -> H.T. | P4: Handles
A5: 4 | B5: Ham Sledge 6.3kg RW Wood | E5: 4 | F5: Chisel Cross Cut 6x12x150 | G5: 15.96 | I5: 4 | J5: HDL BP 700/1100g Poly N/C Yellow | K5: 23.09 | M5: W/B | N5: DAM. | O5: =_xlfn.TEXTJOIN( ,TRUE,M5,N5) -> W/BDAM.
A6: 5 | B6: Ham Boiler Scaling 500g | C6: 55.04 | E6: 5 | F6: Chisel Cross Cut 10x20x200 | G6: 24.51 | I6: 5 | J6: HDL Scutch Poly S/C Soft Grip | K6: 19.87 | M6: UNDRER | N6: FILL | O6: =_xlfn.TEXTJOIN( ,TRUE,M6,N6) -> UNDRER FILL
A7: 6 | B7: Ham Jointer 225g Wood | C7: 40.74 | E7: 6 | F7: Chisel Diamond Point 6x12x150 | G7: 16.59 | I7: 6 | J7: HDL Axe 900g Poly N/C Yellow | K7: 20.86 | M7: BENT/ | N7: OFFSET | O7: =_xlfn.TEXTJOIN( ,TRUE,M7,N7) -> BENT/ OFFSET
A8: 7 | B8: Ham Claw 500g Poly | C8: 58.68 | E8: 7 | F8: Chisel Diamond Point 10x20x200 | G8: 25.45 | I8: 7 | J8: HDL Axe 1.8kg Poly S/C Yellow | K8: 52.5 | M8: DAM. | N8: EYE | O8: =_xlfn.TEXTJOIN( ,TRUE,M8,N8) -> DAM.EYE
A9: 8 | B9: Ham Claw 500g RW Wood | C9: 70.08 | E9: 8 | F9: Chisel Round Nose 6x12x150 | G9: 15.96 | I9: 8 | J9: HDL Claw Poly S/C Soft Grip | K9: 19.68 | M9: CRACK | N9: BOX | O9: =_xlfn.TEXTJOIN( ,TRUE,M9,N9) -> CRACKBOX
A10: 9 | B10: Ham Claw 600g RW Wood | C10: 78.3 | E10: 9 | F10: Chisel Round Nose 10x20x200 | G10: 24.7 | I10: 9 | J10: HDL BP 300g Poly N/C Soft Grip | K10: 21.69 | M10: WRONG | N10: STAMP | O10: =_xlfn.TEXTJOIN( ,TRUE,M10,N10) -> WRONG STAMP
A11: 10 | B11: Ham Claw 600g S/C Poly Handle | C11: 79.3 | E11: 10 | F11: Chisel Flat Cold 12x150 | G11: 16.89 | I11: 10 | J11: HDL BP 500g Poly N/C Soft Grip | K11: 21.69 | M11: CLAWEND | N11: SHORT | O11: =_xlfn.TEXTJOIN( ,TRUE,M11,N11) -> CLAWEND SHORT
A12: 11 | B12: Ham Claw 700g RW Wood | C12: 84.52 | E12: 11 | F12: Chisel Flat Cold 16x175 | G12: 18.44 | I12: 11 | J12: HDL BP 700/1100g Poly N/C Soft Grip | K12: 24.44 | M12: BAD | N12: GRI/POL | O12: =_xlfn.TEXTJOIN(,TRUE,M12,N12) -> BAD GRI/POL
A13: 12 | B13: Ham Claw 700g S/C Poly Handle | C13: 86.22 | E13: 12 | F13: Chisel Flat Cold 16x300 | G13: 23.61 | I13: 12 | J13: HDL Club 1.1kg Poly S/C Soft Grip | K13: 19.9 | M13: COIL | N13: DAMAGE | O13: =_xlfn.TEXTJOIN(,TRUE,M13,N13) -> COIL DAMAGE
A14: 13 | B14: Ham BP 100g RW Wood | C14: 37.1 | E14: 13 | F14: Chisel Flat Cold 12x200 | G14: 19.14 | I14: 13 | J14: HDL Club 1.8kg Poly S/C Soft Grip | K14: 20.19 | M14: TEST | N14: SAMPLES | O14: =_xlfn.TEXTJOIN(,TRUE,M14,N14) -> TEST SAMPLES
A15: 14 | B15: Ham BP 200g Nylon Black | C15: 43.55 | E15: 14 | F15: Chisel Flat Cold 20x200 | G15: 26.49 | I15: 14 | J15: HDL Sledge 1.8kg 400 Poly Soft Grip Falcon | K15: 22.86 | M15: BROKEN | O15: =_xlfn.TEXTJOIN(,TRUE,M15,N15) -> BROKEN
A16: 15 | B16: Ham BP 300g RW Wood | C16: 53.01 | E16: 15 | F16: Chisel Flat Cold 22x225 | G16: 28.95 | I16: 15 | J16: Hdl Sledge 6.3kg 800 Poly Soft Grip | K16: 79.02 | M16: MOULDING | N16: PROBLEM | O16: =_xlfn.TEXTJOIN(,TRUE,M16,N16) -> MOULDING PROBLEM
A17: 16 | B17: Ham BP 300g N/C Soft Grip | C17: 68.47 | E17: 16 | F17: Chisel Flat Cold 20x250 | G17: 30.15 | I17: 16 | J17: Hdl Sledge 3.6kg 600 Poly Soft Grip | K17: 78 | N17: CRACK | O17: =_xlfn.TEXTJOIN(,TRUE,M17,N17) -> CRACK
A18: 17 | B18: Ham BP 500g Rw Wood | C18: 70.67 | E18: 17 | F18: Chisel Flat Cold 25x250 | G18: 40.72 | I18: 17 | J18: Hdl 1.1 Club Wood 250mm | K18: 14 | N18: OTHER | O18: =_xlfn.TEXTJOIN(,TRUE,M18,N18) -> OTHER
A19: 18 | B19: Ham BP 500g N/C Soft Grip | C19: 77.82 | E19: 18 | F19: Chisel Flat Cold 25x300 | G19: 44.53 | I19: 18 | J19: Hdl 1.8 Club Wood 280mm | K19: 21.88 | M19: BAD | N19: FORGING | O19: =_xlfn.TEXTJOIN(,TRUE,M19,N19) -> BAD FORGING
A20: 19 | B20: Ham BP 700g RW Wood | C20: 86.46 | E20: 19 | F20: Chisel Flat Cold 25x350 | G20: 48.39 | I20: 19 | J20: Hdl Claw Wood 345mm | K20: 20.29 | M20: CARCKS | N20: HEAT TREATMENT | O20: =_xlfn.TEXTJOIN(,TRUE,M20,N20) -> CARCKS HEAT TREATMENT
A21: 20 | B21: Ham BP 700g N/C Soft Grip | C21: 88.62 | E21: 20 | F21: Chisel Concrete 25x300 | G21: 45.14 | I21: 20 | J21: Hdl Brick/Scutch 800g Wood | K21: 12.77 | M21: FRG | N21: LAPS | O21: =_xlfn.TEXTJOIN(,TRUE,M21,N21) -> FRGLAPS
A22: 21 | B22: Ham BP 900g RW Wood | C22: 9.67 | E22: 21 | F22: Bar Crow 25x1200 | G22: 131.66 | I22: 21 | J22: Hdl BP Wood 280mm | K22: 7.17 | M22: W/B | N22: DAM. | O22: =_xlfn.TEXTJOIN(,TRUE,M22,N22) -> W/BDAM.
A23: 22 | B23: Ham BP 900g N/C Soft Grip | C23: 96.36 | E23: 22 | F23: Bar Crow 25x1500 | G23: 156.5 | I23: 22 | J23: Hdl BP Wood 300mm | K23: 9.35 | M23: BENT | N23: SCLD | O23: =_xlfn.TEXTJOIN(,TRUE,M23,N23) -> BENTSCLD
A24: 23 | B24: Ham BP 1100g RW Wood | C24: 108.27 | E24: 23 | F24: Bar Crow 25x1800 | G24: 181.24 | I24: 23 | J24: Hdl BP Wood 330mm | K24: 12.9 | M24: BKN | N24: TIP | O24: =_xlfn.TEXTJOIN(,TRUE,M24,N24) -> BKNTIP
A25: 24 | B25: Ham BP 1100 N/C Soft Grip | C25: 118.37 | E25: 24 | F25: Bar Crow 32x1800 | G25: 259.12 | I25: 24 | J25: Hdl BP Wood 350mm | K25: 21.22 | M25: MAT | N25: CRKS | O25: =_xlfn.TEXTJOIN(,TRUE,M25,N25) -> MATCRKS
A26: 25 | B26: Ham Club 1.1kg Wood | C26: 94.98 | E26: 25 | F26: Hammer Chipping | G26: 35.87 | I26: 25 | J26: Hdl BP Wood 380mm | K26: 26.71 | N26: U/FILL | O26: =_xlfn.TEXTJOIN(,TRUE,M26,N26) -> U/FILL
A27: 26 | B27: Ham Club 1.1kg S/C Soft Grip | C27: 103.25 | E27: 26 | F27: Knife Hacking PVC Grip | G27: 31.11 | I27: 26 | J27: Hdl BP Wood 400mm | K27: 32.67 | O27: POOR ASSMBLY
A28: 27 | B28: Ham Club 1.8kg Wood | C28: 0 | E28: 27 | F28: Stamper Round 160mm Dia | G28: 209.35 | I28: 27 | J28: Hdl BP Wood 425mm | K28: 23.96
A29: 28 | B29: Ham Club 1.8kg S/C Soft Grip | C29: 129.29 | E29: 28 | F29: Stamper Sq. 150mm | G29: 164.23 | I29: 28 | J29: Hdl Sledge Wood 600mm | K29: 47.44
A30: 29 | B30: Ham Brick Chisel Wood | C30: 79.96 | E30: 29 | F30: Bar Tommy 20x450mm | G30: 49.43 | I30: 29 | J30: Hdl Sledge Wood 750mm | K30: 32.04
A31: 30 | B31: Ham Scutch Wood | C31: 89.57 | E31: 30 | F31: Bar Tommy 20x600mm | G31: 59.81 | I31: 30 | J31: Hdl Sledge Wood 900mm | K31: 74.9
A32: 31 | B32: Ham Scutch S/C Soft Grip | C32: 87.06 | E32: 31 | F32: Bar Wrecking 20x300mm | G32: 52.51 | I32: 31 | J32: Hdl Joiner Wood 280mm | K32: 7.11
A33: 32 | B33: Ham Din 500g Wood | C33: 96.98 | E33: 32 | F33: Bar Wrecking 20x450mm | G33: 60.91 | I33: 32 | J33: Hdl Fitter Wood 320mm | K33: 3.21
A34: 33 | B34: Ham Drill 1.8kg CCL Heads | C34: 55.7 | E34: 33 | F34: Bar Wrecking 20x600mm | G34: 72.41 | I34: 33 | J34: Hdl Boiler Scaling Wood 300mm | K34: 9.14
A35: 34 | B35: Ham Sledge 3.6kg CCL Heads | C35: 96.73 | E35: 34 | F35: Bar Wrecking 20x750mm | G35: 82.67 | I35: 34 | J35: Hdl Broom Steel Plastic | K35: 13.45
A36: 35 | B36: Ham Sledge 10lb CCL Heads | C36: 193.31 | E36: 35 | F36: Bar Wrecking 20x900mm | G36: 83.14 | I36: 35 | J36: Hdl Rake Steel Plastic | K36: 13.45
A37: 36 | B37: Ham Sledge 6.3kg RW Heads | C37: 232.24 | E37: 36 | F37: Digging Bars | G37: 74.1 | I37: 36 | J37: Hd Broom 300mm Brite / Fitting | K37: 35.9
A38: 37 | B38: Ham Club 2.5lb CCL Heads | C38: 319.15 | I38: 37 | J38: Hd Slasher | K38: 40.19
A39: 38 | B39: Ham Club 1.8kg CCL Heads | C39: 69.73
A40: 39 | B40: Ham Drill 1.8kg P/Handle Black | C40: 96.65
...

Sheet SCRAP DATA
A1: Date | B1: Month | C1: Year | D1: Prod Type | E1: PRODUCT | F1: FG Code | G1: Qty | H1: Unit Cost | I1: Total Cost | J1: Scrap Type
A2: 45474 | B2: JULY | C2: 2024 | D2: Hammer | E2: Ham Claw 500g Poly | G2: 4 | H2: =VLOOKUP(E2,TABLE!$B$1:$C$137,2,FALSE) -> 72.31 | I2: =G2*H2 -> 289.24 | J2: CLW END.SHRT
A3: 45474 | B3: JULY | C3: 2024 | D3: Hammer | E3: Ham Drill 1.8kg P/Handle Black | G3: 13 | H3: =VLOOKUP(E3,TABLE!$B$1:$C$137,2,FALSE) -> 114.33 | I3: =G3*H3 -> 1486.29 | J3: BAD.FRG
A4: 45474 | B4: JULY | C4: 2024 | D4: Hammer | E4: Ham Spalling 6.3kg P/Handle Black CCL | G4: 5 | H4: =VLOOKUP(E4,TABLE!$B$1:$C$137,2,FALSE) -> 358.99 | I4: =G4*H4 -> 1794.95 | J4: CRACK
A5: 45474 | B5: JULY | C5: 2024 | D5: Hammer | E5: Ham Claw 700g S/C Poly Handle | G5: 2 | H5: =VLOOKUP(E5,TABLE!$B$1:$C$137,2,FALSE) -> 85.75 | I5: =G5*H5 -> 171.5 | J5: CLW END.SHRT
A6: 45474 | B6: JULY | C6: 2024 | D6: Hammer | E6: Ham BP 500g N/C Soft Grip | G6: 6 | H6: =VLOOKUP(E6,TABLE!$B$1:$C$137,2,FALSE) -> 77.69 | I6: =G6*H6 -> 466.14 | J6: DAM.EYE
A7: 45474 | B7: JULY | C7: 2024 | D7: Hammer | E7: Ham Club 1.1kg S/C Soft Grip | G7: 3 | H7: =VLOOKUP(E7,TABLE!$B$1:$C$137,2,FALSE) -> 97.22 | I7: =G7*H7 -> 291.66 | J7: DAM.EYE
A8: 45474 | B8: JULY | C8: 2024 | D8: Hammer | E8: Ham Club 1.8kg S/C Soft Grip | G8: 10 | H8: =VLOOKUP(E8,TABLE!$B$1:$C$137,2,FALSE) -> 85 | I8: =G8*H8 -> 850 | J8: DAM.EYE
A9: 45474 | B9: JULY | C9: 2024 | D9: Iron Tools | E9: Bolst Electrician 55mm | G9: 3 | H9: =VLOOKUP(E9,TABLE!$B$1:$C$137,2,FALSE) -> 32.32 | I9: =G9*H9 -> 96.96 | J9: WL.DAM
A10: 45474 | B10: JULY | C10: 2024 | D10: Iron Tools | E10: Chisel Flat Cold 12x150 | G10: 3 | H10: =VLOOKUP(E10,TABLE!$B$1:$C$137,2,FALSE) -> 16.08 | I10: =G10*H10 -> 48.24 | J10: WL.DAM
A11: 45474 | B11: JULY | C11: 2024 | D11: Iron Tools | E11: Chisel Flat Cold 20x200 | G11: 2 | H11: =VLOOKUP(E11,TABLE!$B$1:$C$137,2,FALSE) -> 23.91 | I11: =G11*H11 -> 47.82 | J11: WL.DAM
A12: 45474 | B12: JULY | C12: 2024 | D12: Iron Tools | E12: Chisel Flat Cold 20x250 | G12: 2 | H12: =VLOOKUP(E12,TABLE!$B$1:$C$137,2,FALSE) -> 27.14 | I12: =G12*H12 -> 54.28 | J12: WL.DAM
A13: 45474 | B13: JULY | C13: 2024 | D13: Iron Tools | E13: Chisel Flat Cold 25x250 | G13: 7 | H13: =VLOOKUP(E13,TABLE!$B$1:$C$137,2,FALSE) -> 34.83 | I13: =G13*H13 -> 243.81 | J13: WL.DAM
... A58: 45536 | B58: SEPTEMBER | C58: 2024 | D58: Hammer | E58: Ham Club 1.8kg S/C Soft Grip | G58: 4 | H58: =VLOOKUP(E58,TABLE!$B$1:$C$137,2,FALSE) -> 85 | I58: =G58*H58 -> 340 | J58: DAM.EYE
A59: 45536 | B59: SEPTEMBER | C59: 2024 | D59: Hammer | E59: Rake Head | G59: 8 | H59: =VLOOKUP(E59,TABLE!$B$1:$C$137,2,FALSE) -> 30.18 | I59: 692.16 | J59: MOULDING PROBLEM
A60: 45536 | B60: SEPTEMBER | C60: 2024 | D60: Iron Tools | E60: Bolster 100mm | G60: 9 | H60: =VLOOKUP(E60,TABLE!$B$1:$C$137,2,FALSE) -> 49.25 | I60: =G60*H60 -> 443.25 | J60: BAD.FRG
A61: 45536 | B61: SEPTEMBER | C61: 2024 | D61: Iron Tools | E61: Chisel Flat Cold 25x350 | G61: 7 | H61: =VLOOKUP(E61,TABLE!$B$1:$C$137,2,FALSE) -> 44.78 | I61: =G61*H61 -> 313.46 | J61: BAD.FRG
A62: 45536 | B62: SEPTEMBER | C62: 2024 | D62: Iron Tools | E62: Chisel Flat Cold 22x225 | G62: 3 | H62: =VLOOKUP(E62,TABLE!$B$1:$C$137,2,FALSE) -> 26.1 | I62: =G62*H62 -> 78.3 | J62: WL.DAM
A63: 45536 | B63: SEPTEMBER | C63: 2024 | D63: Iron Tools | E63: Chisel Flat Cold 20x250 | G63: 7 | H63: =VLOOKUP(E63,TABLE!$B$1:$C$137,2,FALSE) -> 27.14 | I63: =G63*H63 -> 189.98 | J63: WL.DAM
A64: 45536 | B64: SEPTEMBER | C64: 2024 | D64: Handles | E64: Hdl Boiler Scaling Wood | G64: 3 | H64: =VLOOKUP(E64,TABLE!$B$1:$C$137,2,FALSE) -> 7.62 | I64: =G64*H64 -> 22.86 | J64: BRKN
A65: 45536 | B65: SEPTEMBER | C65: 2024 | D65: Handles | E65: Hdl Rake Steel Plastic | G65: 10 | H65: =VLOOKUP(E65,TABLE!$B$1:$C$137,2,FALSE) -> 11.59 | I65: =G65*H65 -> 115.9 | J65: BRKN
A66: 45566 | B66: OCTOBER | C66: 2024 | D66: Hammer | E66: Ham Claw 500g Poly | G66: 14 | H66: =VLOOKUP(E66,TABLE!$B$1:$C$137,2,FALSE) -> 72.31 | I66: =G66*H66 -> 1012.34 | J66: BAD.FRG
A67: 45566 | B67: OCTOBER | C67: 2024 | D67: Hammer | E67: Ham Drill 1.8kg P/Handle Black | G67: 13 | H67: =VLOOKUP(E67,TABLE!$B$1:$C$137,2,FALSE) -> 114.33 | I67: =G67*H67 -> 1486.29 | J67: BAD.FRG
A68: 45566 | B68: OCTOBER | C68: 2024 | D68: Handles | E68: Ham Sledge 6.3kg P/Handle Black CCL | G68: 1 | H68: =VLOOKUP(E68,TABLE!$B$1:$C$137,2,FALSE) -> 358 | I68: =G68*H68 -> 358 | J68: BAD.FRG
A69: 45566 | B69: OCTOBER | C69: 2024 | D69: Hammer | E69: Ham BP 1100 N/C Soft Grip | G69: 1 | H69: =VLOOKUP(E69,TABLE!$B$1:$C$137,2,FALSE) -> 115.36 | I69: =G69*H69 -> 115.36 | J69: BAD.FRG
A70: 45566 | B70: OCTOBER | C70: 2024 | D70: Hammer | E70: Ham Club 1.1kg S/C Soft Grip | G70: 2 | H70: =VLOOKUP(E70,TABLE!$B$1:$C$137,2,FALSE) -> 97.22 | I70: =G70*H70 -> 194.44 | J70: BAD.FRG
A71: 45566 | B71: OCTOBER | C71: 2024 | D71: Hammer | E71: Ham Club 1.8kg S/C Soft Grip | G71: 6 | H71: =VLOOKUP(E71,TABLE!$B$1:$C$137,2,FALSE) -> 85 | I71: =G71*H71 -> 510 | J71: BAD.FRG
... A308: 45809 | B308: JUNE | C308: 2025 | D308: Handles | E308: HDL Club 1.8kg Poly S/C Soft Grip | G308: 1 | H308: =VLOOKUP(E308,TABLE!$B$1:$C$137,2,FALSE) -> 20.04 | I308: =G308*H308 -> 20.04 | J308: POOR ASSMBLY
A309: 46059 | B309: FEBRUARY | C309: 2026 | D309: Iron Tools | E309: Chisel Flat Cold 25x350 | F309: FG02750 | G309: 1 | H309: =VLOOKUP(E309,TABLE!$B$1:$C$137,2,FALSE) -> 44.78 | I309: =G309*H309 -> 44.78 | J309: W/BDAM.
A310: 46059 | B310: FEBRUARY | C310: 2026 | D310: Hammers | E310: Ham Claw 500g Poly | F310: FG04130 | G310: 3 | H310: =VLOOKUP(E310,TABLE!$B$1:$C$137,2,FALSE) -> 72.31 | I310: =G310*H310 -> 216.93 | J310: CARCKS HEAT TREATMENT
A311: 46059 | B311: FEBRUARY | C311: 2026 | D311: Iron Tools | E311: Chisel Flat Cold 25x300 | F311: FG02760 | G311: 1 | H311: =VLOOKUP(E311,TABLE!$B$1:$C$137,2,FALSE) -> 38.27 | I311: =G311*H311 -> 38.27 | J311: W/BDAM.
A312: 46059 | B312: FEBRUARY | C312: 2026 | D312: Iron Tools | E312: Chisel Flat Cold 25x250 | F312: FG02725 | G312: 4 | H312: =VLOOKUP(E312,TABLE!$B$1:$C$137,2,FALSE) -> 34.83 | I312: =G312*H312 -> 139.32 | J312: BAD FORGING
A313: 46059 | B313: FEBRUARY | C313: 2026 | D313: Hammers | E313: Ham Club 1.8kg S/C Soft Grip | F313: FG05214 | G313: 1 | H313: =VLOOKUP(E313,TABLE!$B$1:$C$137,2,FALSE) -> 85 | I313: =G313*H313 -> 85 | J313: BAD FORGING
A314: 46059 | B314: FEBRUARY | C314: 2026 | D314: Hammers | E314: Ham Drill 1.8kg P/Handle Black | F314: FG05075 | G314: 1 | H314: =VLOOKUP(E314,TABLE!$B$1:$C$137,2,FALSE) -> 114.33 | I314: =G314*H314 -> 114.33 | J314: BAD FORGING
A315: 46059 | B315: FEBRUARY | C315: 2026 | D315: Iron Tools | E315: Bolst Electrician 55mm | F315: FG02630 | G315: 1 | H315: =VLOOKUP(E315,TABLE!$B$1:$C$137,2,FALSE) -> 32.32 | I315: =G315*H315 -> 32.32 | J315: W/BDAM.
A316: 46059 | B316: FEBRUARY | C316: 2026 | D316: Iron Tools | E316: Chisel Flat Cold 20x250 | F316: FG02720 | G316: 1 | H316: =VLOOKUP(E316,TABLE!$B$1:$C$137,2,FALSE) -> 27.14 | I316: =G316*H316 -> 27.14 | J316: W/BDAM.
A317: 46059 | B317: FEBRUARY | C317: 2026 | D317: Iron Tools | E317: Bar Wrecking 20x600mm | F317: FG02985 | G317: 1 | H317: =VLOOKUP(E317,TABLE!$B$1:$C$137,2,FALSE) -> 64.46 | I317: =G317*H317 -> 64.46 | J317: BAD FORGING
A318: 46059 | B318: FEBRUARY | C318: 2026 | D318: Handles | E318: HDL Club 1.8kg Poly S/C Soft Grip | F318: CS05214 | G318: 2 | H318: =VLOOKUP(E318,TABLE!$B$1:$C$137,2,FALSE) -> 20.04 | I318: =G318*H318 -> 40.08 | J318: Poor Assembly

Sheet HAMMER
A3: Prod Type | B3: Hammer
A5: Sum of Qty | B5: Column Labels
A6: Row Labels | B6: BAD.FRG | C6: BENT/ OFFSET | D6: CLW END.SHRT | E6: CRACK | F6: DAM.EYE | G6: MOULDING PROBLEM | H6: WL.DAM | I6: Grand Total
A7: Ham Club 1.8kg S/C Soft Grip | B7: 36 | F7: 14 | I7: 50
A8: Ham Drill 1.8kg P/Handle Black | B8: 82 | I8: 82
A9: Ham Claw 500g Poly | B9: 65 | D9: 38 | E9: 3 | H9: 2 | I9: 108
A10: Ham Claw 700g S/C Poly Handle | B10: 49 | D10: 69 | H10: 1 | I10: 119
A11: Axe 0.9kg Composite | B11: 382 | C11: 2 | E11: 4 | H11: 1 | I11: 389
A12: Grand Total | B12: 614 | C12: 2 | D12: 107 | E12: 7 | F12: 14 | H12: 4 | I12: 748

Sheet IRONTOOL
A2: Prod Type | B2: Iron Tools
A4: Sum of Qty | B4: Column Labels
A5: Row Labels | B5: WL.DAM | C5: BAD.FRG | D5: BRKN.TIP | E5: BENT/ OFFSET | F5: Grand Total
A6: Chisel Flat Cold 25x250 | B6: 32 | C6: 1 | F6: 33
A7: Chisel Flat Cold 25x350 | B7: 35 | C7: 13 | D7: 4 | E7: 3 | F7: 55
A8: Bolst Electrician 55mm | B8: 61 | C8: 2 | F8: 63
A9: Bolster 100mm | B9: 48 | C9: 32 | F9: 80
A10: Chisel Flat Cold 25x300 | B10: 88 | F10: 88
A11: Grand Total | B11: 264 | C11: 48 | D11: 4 | E11: 3 | F11: 319

Sheet HANDLE
A1: Prod Type | B1: Handles
A2: Year | B2: (Multiple Items)
A4: Sum of Qty | B4: Column Labels
A5: Row Labels | B5: BRKN | C5: MOULDING PROBLEM | D5: POOR ASSMBLY | E5: ECR | F5: Grand Total
A6: HDL Axe 1.8kg Poly S/C Yellow | C6: 49 | D6: 1 | F6: 50
A7: HDL BP 700/1100g Poly N/C Soft Grip | C7: 1 | E7: 80 | F7: 81
A8: Hdl Rake Steel Plastic | B8: 67 | C8: 67 | F8: 134
A9: HDL BP 500g Poly N/C Soft Grip | E9: 172 | F9: 172
A10: HDL Claw Poly S/C Soft Grip | C10: 180 | D10: 3 | F10: 183
A11: Grand Total | B11: 67 | C11: 297 | D11: 4 | E11: 252 | F11: 620

Sheet TABLE
A1: NO | B1: PRODUCT | C1: Value
A2: 1 | B2: Axe 0.9kg Composite | C2: 76.89
A3: 2 | B3: Combo Rake & Broom | C3: 86.52
A4: 3 | B4: Rake Head | C4: 30.18
A5: 4 | B5: Knife Double Edge Slasher | C5: 114.8
A6: 5 | B6: Ham Boiler Scaling 500g | C6: 50.54
A7: 6 | B7: Ham Claw 500g Poly | C7: 72.31
A8: 7 | B8: Ham Jointer 225g Wood | C8: 39.4
A9: 8 | B9: Ham Sledge 6.3kg RW Heads | C9: 281.45
A10: 9 | B10: Ham Din 500g Wood | C10: 51.36
A11: 10 | B11: Ham Drill 1.8kg P/Handle Black | C11: 114.33
A12: 11 | B12: Ham Sledge 3.6kg P/Handle Black CCL | C12: 241.14
A13: 12 | B13: Ham Sledge 4.5kg P/Handle Black CCL | C13: 272.14
... A45: 44 | B45: Axe 1.8kg P/Handle yellow | C45: 181.83
A46: 45 | B46: Ham Sledge 1.8kg RW Wood
A47: 46 | B47: Ham Sledge 3.6kg RW Wood
A48: 47 | B48: Ham Sledge 4.5kg RW Wood
A49: 48 | B49: Ham Sledge 6.3kg RW Wood
A50: 49 | B50: Ham Claw 500g RW Wood
A51: 50 | B51: Ham Claw 600g RW Wood
A52: 51 | B52: Ham Claw 700g RW Wood
A53: 52 | B53: Ham BP 300g RW Wood
A54: 53 | B54: Ham BP 300g N/C Soft Grip
A55: 54 | B55: Ham BP 500g Rw Wood | C55: 68.2
A56: 55 | B56: Ham BP 700g RW Wood | C56: 83.13
A57: 56 | B57: Ham BP 900g RW Wood
A58: 57 | B58: Ham BP 1100g RW Wood | C58: 83.13
A59: 58 | B59: Ham Club 1.1kg Wood | C59: 87.8
A60: 59 | B60: Bolster 100mm | C60: 49.25
A61: 60 | B61: Bolster 100mm PVC Grip | C61: 58.78
A62: 61 | B62: Bolst Electrician 55mm | C62: 32.32
A63: 62 | B63: Chisel Cross Cut 6x12x150 | C63: 22.16
A64: 63 | B64: Chisel Cross Cut 10x20x200 | C64: 23.28
A65: 64 | B65: Chisel Round Nose 6x12x150 | C65: 22.16
A66: 65 | B66: Chisel Round Nose 10x20x200 | C66: 23.28
A67: 66 | B67: Chisel Flat Cold 12x150 | C67: 16.08
A68: 67 | B68: Chisel Flat Cold 16x175 | C68: 17.8
A69: 68 | B69: Chisel Flat Cold 12x200 | C69: 18.54
... A94: 93 | B94: Chisel Diamond Point 10x20x200 | C94: 23.28
A95: 94 | B95: Chisel Flat Cold 16x300
...

Sheet HAMMER CST
A1: Prod Type | B1: Hammer
A2: Year | B2: (All)
A4: Sum of Total Cost | B4: Column Labels
A5: Row Labels | B5: BAD.FRG | C5: CLW END.SHRT | D5: CRACK | E5: TEST SAMPLES | F5: WL.DAM | G5: BENT/ OFFSET | H5: MOULDING PROBLEM | I5: DAM.EYE | J5: Grand Total
A6: Ham Claw 500g Poly | B6: 4700.15 | C6: 2747.78 | D6: 216.93 | E6: 650.79 | F6: 144.62 | J6: 8460.27
A7: Ham Drill 1.8kg P/Handle Black | B7: 9375.06 | E7: 114.33 | J7: 9489.39
A8: Ham Claw 700g S/C Poly Handle | B8: 4201.75 | C8: 5916.75 | F8: 85.75 | J8: 10204.25
A9: Ham Sledge 6.3kg P/Handle Black CCL | B9: 8950 | D9: 1790 | J9: 10740
A10: Axe 0.9kg Composite | B10: 29371.98 | D10: 307.56 | F10: 76.89 | G10: 153.78 | J10: 29910.21
A11: Grand Total | B11: 56598.94 | C11: 8664.53 | D11: 2314.49 | E11: 765.12 | F11: 307.26 | G11: 153.78 | J11: 68804.12

Sheet IRONTOOL CST
A1: Prod Type | B1: (Multiple Items)
A2: Year | B2: (Multiple Items)
A4: Sum of Total Cost | B4: Column Labels
A5: Row Labels | B5: WL.DAM | C5: BRKN.TIP | D5: BAD.FRG | E5: BENT/ OFFSET | F5: Grand Total
A6: Chisel Flat Cold 25x300 | B6: 956.75 | F6: 956.75
A7: Bolst Electrician 55mm | B7: 1098.88 | D7: 64.64 | F7: 1163.52
A8: Hammer Chipping | C8: 1214.36 | F8: 1214.36
A9: Bolster 100mm | B9: 738.75 | D9: 541.75 | F9: 1280.5
A10: Chisel Flat Cold 25x350 | B10: 1209.06 | D10: 89.56 | F10: 1298.62
A11: Grand Total | B11: 4003.44 | C11: 1214.36 | D11: 695.95 | F11: 5913.75

Sheet HANDLE CST
A1: Prod Type | B1: Handles
A2: Year | B2: (Multiple Items)
A4: Sum of Total Cost | B4: Column Labels
A5: Row Labels | B5: MOULDING PROBLEM | C5: ECR | D5: POOR ASSMBLY | E5: Grand Total
A6: Ham Sledge 6.3kg P/Handle Black CCL | D6: 1790 | E6: 1790
A7: HDL BP 700/1100g Poly N/C Soft Grip | B7: 26 | C7: 2080 | E7: 2106
A8: HDL Axe 1.8kg Poly S/C Yellow | B8: 2562.7 | D8: 52.3 | E8: 2615
A9: HDL Claw Poly S/C Soft Grip | B9: 3519 | D9: 58.65 | E9: 3577.65
A10: HDL BP 500g Poly N/C Soft Grip | C10: 3968.04 | E10: 3968.04
A11: Grand Total | B11: 6107.7 | C11: 6048.04 | D11: 1900.95 | E11: 14056.69

Sheet HAMMER CON
A1: Prod Type | B1: Hammer
A2: Year | B2: (All)
A4: Row Labels | B4: Sum of Qty
A5: BAD.FRG | B5: 0.75593952
A6: CLW END.SHRT | B6: 0.11771058
A7: MOULDING PROBLEM | B7: 0.05075594
A8: DAM.EYE | B8: 0.024838013
A9: CRACK | B9: 0.023758099
A10: TEST SAMPLES | B10: 0.018358531
A11: WL.DAM | B11: 0.0064794816
A12: BENT/ OFFSET | B12: 0.0021598272
A13: Grand Total | B13: 1

Sheet IRONTOOL CON
A1: Prod Type | B1: Iron Tools
A2: Year | B2: (All)
A4: Row Labels | B4: Sum of Qty
A5: WL.DAM | B5: 0.77892562
A6: BAD.FRG | B6: 0.13429752
A7: BRKN.TIP | B7: 0.07231405
A8: BENT/ OFFSET | B8: 0.01446281
A9: Grand Total | B9: 1

Sheet HANDLE CON
A1: Prod Type | B1: Handles
A2: Year | B2: (All)
A4: Row Labels | B4: Sum of Qty
A5: MOULDING PROBLEM | B5: 0.35645472
A6: ECR | B6: 0.24277457
A7: BRKN | B7: 0.2283237
A8: POOR ASSMBLY | B8: 0.14643545
A9: CRACK | B9: 0.02504817
A10: BAD.FRG | B10: 0.00096339114
A11: Grand Total | B11: 1

Sheet top5
A1: Year | B1: 2025
A3: Sum of Total Cost | B3: Column Labels
A4: Row Labels | B4: BAD.FRG | C4: BENT/ OFFSET | D4: BRKN | E4: BRKN.TIP | F4: CLW END.SHRT | G4: CRACK | H4: MOULDING PROBLEM | I4: POOR ASSMBLY | J4: TEST SAMPLES | K4: WL.DAM | L4: ECR | M4: Grand Total
A5: Axe 0.9kg Composite | B5: 29295.09 | G5: 307.56 | K5: 76.89 | M5: 29679.54
A6: Ham Sledge 6.3kg P/Handle Black CCL | B6: 8950 | G6: 358 | I6: 1790 | M6: 11098
A7: Ham Claw 500g Poly | B7: 2313.92 | F7: 1807.75 | G7: 216.93 | H7: 72.31 | I7: 72.31 | J7: 216.93 | K7: 144.62 | M7: 4844.77
A8: Ham Club 1.8kg S/C Soft Grip | B8: 2295 | H8: 85 | I8: 1615 | J8: 85 | M8: 4080
A9: HDL BP 500g Poly N/C Soft Grip | L9: 3968.04 | M9: 3968.04
A10: Grand Total | B10: 42854.01 | F10: 1807.75 | G10: 882.49 | H10: 157.31 | I10: 3477.31 | J10: 301.93 | K10: 221.51 | L10: 3968.04 | M10: 53670.35

Sheet top5 (2)
A1: Year | B1: 2025
A3: Sum of Qty | B3: Column Labels
A4: Row Labels | B4: BAD.FRG | C4: BENT/ OFFSET | D4: BRKN | E4: BRKN.TIP | F4: CLW END.SHRT | G4: CRACK | H4: MOULDING PROBLEM | I4: POOR ASSMBLY | J4: TEST SAMPLES | K4: WL.DAM | L4: ECR | M4: Grand Total
A5: Axe 0.9kg Composite | B5: 381 | G5: 4 | K5: 1 | M5: 386
A6: HDL Claw Poly S/C Soft Grip | H6: 180 | I6: 3 | M6: 183
A7: HDL BP 500g Poly N/C Soft Grip | L7: 172 | M7: 172
A8: Hdl Rake Steel Plastic | D8: 67 | H8: 67 | M8: 134
A9: HDL BP 700/1100g Poly N/C Soft Grip | H9: 1 | L9: 80 | M9: 81
A10: Grand Total | B10: 381 | D10: 67 | G10: 4 | H10: 248 | I10: 3 | K10: 1 | L10: 252 | M10: 956

Sheet HAMMER (2)
A5: Sum of Qty | B5: Column Labels
A6: Row Labels | B6: Hammer | C6: Handles | D6: Iron Tools | E6: Grand Total
A7: 2024 | B7: 309 | C7: 279 | D7: 260 | E7: 848
A8: Jul | B8: 48 | C8: 59 | D8: 43 | E8: 150
A9: Aug | B9: 48 | C9: 64 | D9: 53 | E9: 165
A10: Sep | B10: 37 | C10: 13 | D10: 26 | E10: 76
A11: Oct | B11: 90 | C11: 47 | D11: 70 | E11: 207
A12: Nov | B12: 53 | C12: 30 | D12: 48 | E12: 131
A13: Dec | B13: 33 | C13: 66 | D13: 20 | E13: 119
A14: 2025 | B14: 617 | C14: 759 | D14: 224 | E14: 1600
A15: Jan | B15: 36 | C15: 57 | D15: 33 | E15: 126
A16: Feb | B16: 329 | C16: 45 | D16: 28 | E16: 402
A17: Mar | B17: 53 | C17: 51 | D17: 37 | E17: 141
A18: Apr | B18: 50 | C18: 177 | D18: 31 | E18: 258
A19: May | B19: 45 | C19: 263 | D19: 52 | E19: 360
A20: Jun | B20: 104 | C20: 166 | D20: 43 | E20: 313
A21: Grand Total | B21: 926 | C21: 1038 | D21: 484 | E21: 2448
